Workbook

Sheet REKAP
A1: NO | B1: TANGGAL | C1: MEDIA ADUAN | D1: NAMA / NOMOR | E1: JENIS | F1: SUBDIT | G1: PERTANYAAN | H1: JAWABAN
A2: 1 | B2: 45422 | C2: WHATSAPP | D2: 62 857-3004-2502 | E2: SAMSAT | F2: REGIDENT | G2: - Selamat pagi Bapak/Ibu, saya Rizki dari Surabaya, mohon izin bertanya/info, untuk pengurusan kartu induk BPKB yang hilang perlu waktu berapa lama ya? Atau adakah nomor/media/kanal yang bisa dihubungi untuk bertanya karena saya cari melalui internet/medsos sepertinya belum ada? Mohon bantuannya bapak/ibu. Terimakasih🙏🏻🙏🏻 | H2: - bisa dibantu nopolnya? kami bantu cek
A3: 2 | B3: 45426 | C3: WHATSAPP | D3: 62 822-4555-4323 | E3: LAIN-LAIN | G3: - Assalamualaikum pak selamat siang - Saya mau ngambil stnk tanpa harus di sidang gimana caranya? - Ini tandanya polsek gubeng, Tapi malah di suruh sidang di Sukomanunggal. - Katanya bapak nya saya di suruh (ngurus atau disidang) Nah saya pilih di urus pak biar cepat dan clear. | H3: - walaikumsalam selamat siang - ada yg bisa kami bantu - Wilayah mana pak/bu - ada no tilangnya kita bantu cek terlebih dahulu - silahkan datang di satpas colombo untuk meminta kode briva di kantor tilang polrestabes surabaya
A4: 3 | B4: 45428 | C4: WHATSAPP | D4: +62 856-5582-1443 | E4: SAMSAT | G4: -Selamat pagi -Perkenalkan saya Herlambang, -Mohon bantuan petunjuknya Bapak/Ibu, untuk persyaratan penerbitan Surat Rekomendasi Polda Jatim, untuk keperluan pendaftaran STNK & BPKB kendaraan di kantor Samsat daerah Jawa Timur. -Domisili Banyuwangi Pak -Namun saat ini kendaraan berada di Bekasi, Jawa Barat Pak/Bu -Baik terimakasih atas informasinya, Izin bertanya apakah persyaratan penerbitan Surat Rekomendasi bisa disampaikan melalui jasa pengiriman dokumen (Pos) atau melalui email Pak/Bu?- -Karena saat ini saya tinggal di bekasi namun data KTP masih beralamat di Banyuwangi. Terimakasih🙏 -Baik Bapak/Ibu terimakasih atas informasinya🙏 -Sehubungan dengan persyaratan yang dimohonkan untuk penerbitan surat Rekomendasi Polda Jatim, ada persamaan berkas yang disampaikan untuk penerbitan BPKB dari kantor Samsat Banyuwangi sesuai persyaratan terlampir Pak/Bu -Mohon izin bertanya kembali Pak/bu apakah ketika pengajuan permohonan penerbitan surat rekomendasi Polda Jatim Dokumen Asli hanya untuk ditunjukkan dan yang disampaikan untuk surat rekomendasi adalah dokumen duplikat/copy Bapak/Ibu? | H4: -pemenang lelang domisili mana pak/bu -atau bisa difotokan dokumen lelalng nya -mohon maaf tidak bisa, dikarenakan butuh berkas asli, dan apabila dikirim melalui POS dikhawatirkan tidak terkirim, trims -Untuk surat yg dibawa ke polda harus asli pak/bu
A5: 5 | B5: 45437 | C5: FACEBOOK | D5: Sloow Broow | E5: SAMSAT | G5: Untuk Sidoarjo dimana aja untuk bayar pajak spdh | H5: silahkan datang di samsat corner lotte mart,samsat keliling kota,samsat keliling krian, samsat payment point wadung asri,samsat payment point samsat lama,samsat payment point bank jatim taman, samsat payment point puspa agro terima kasih
A6: 6 | B6: 45438 | C6: FACEBOOK | D6: Anjam Unyil | E6: SAMSAT | G6: 1. Bayar pajak kendaraan tanpa ktp pemilik pertama apakah bisa??? 2.Siap 🙏🙏🙏 | H6: mohon maaf tidak bisa, apabila sudah berpindah tangan bisa balik nama di samsat asal, terima kasih
A7: 4 | B7: 45439 | C7: WHATSAPP | D7: +62 822-3061-6978 | E7: LAIN-LAIN | G7: -Selamat siang, betul dengan akun whatsapp polsek tegalsari surabaya? -Mohon maaf, adakah kontak whatsapp polsek tegalsari yang bisa saya hubungi Pak/Bu? -Saya ingin menanyakan perihal kerabat saya yg terakhir kali infonya sedang berada di polsek tegalsari Surabaya🙏🏻- -Baik, terimakasih bantuannya Pak/Bu 🙏🏻 -Baik, untuk nomor whatsapp nya belum ada ya Pak/Bu? | H7: -dengan rtmc polda jatim -Ada yg bisa dibantu -Mhn waktu -izin pak/bu ini untuk nomor dari polsek tegal sari 031 5341052 -untuk sementara nomor dari polsek tegalsari hanya ini saja
A8: 7 | B8: 45439 | C8: FACEBOOK | D8: Airin Dan Aura | E8: SIM | G8: Maaf, bs untuk upgrade SIM A ke B1 | H8: mohon maaf tidak bisa sim keliling hanya melayani perpanjangan sim A dan C saja, terima kasih
A9: 8 | B9: 45440 | C9: FACEBOOK | D9: Eko Anis M | E9: SIM | G9: 1. Kalau perpanjang SIM maksimal berapa hari sebelum masa berlaku 2. ini berlaku seluruh Jawa timur | H9: 1. sebelum masa berlaku habis 2. iya pak
A10: 1 | B10: 45449 | C10: FACEBOOK | D10: Tulus Machfudi | E10: SIM | F10: REGIDENT | G10: 1. SIM saya surabaya, sekarang KTP Sidoarjo. Mau memperpanjang SIM. Mohon pencerahan dari ditlantas Polda. Terima kasih. 2.Terima kasih pencerahannya. | H10: 1. kalau SIM A dan C bisa diperpanjang dimana saja mas, asal SIM tersebut belum kadaluarsa dan mengikuti KTP alamat baru
A11: 2 | B11: 45449 | C11: FACEBOOK | D11: Irosab | E11: SIM | G11: 1. Apakah di sim keliling di sediakan tempat psikologi dan surat kesehatan | H11: 1. sudah tersedia
A12: 3 | B12: 45449 | C12: FACEBOOK | D12: Hayik Depp | E12: SAMSAT | G12: 1. mutasi masuk apakah bisa langsung ke samsat tujuan? 2. mobil plat N Malang masuk ke Surabaya samsat Kedung Cowek dan mobil plat Bandar Lampung masuk ke Surabaya samsat Kedung Cowek ndan, mohon pencerahannya, terima kasih 3.sudah tidak perlu cabut berkas lagi di samsat asal ya ndan? 4. siap, terima kasih infonya ndan 🙏🙏🙏 | H12: 1.dari samsat mana kemana pak 2. apabila dari plat N langsung ke samsat tujuan namun untuk plat luar wilayah jawa timur ke polda terlebih dahulu, trims 3. tetap cabut di samsat asal pak
A13: 4 | B13: 45449 | C13: FACEBOOK | D13: Taufiq Cholis | E13: SIM | G13: 1. Perpanjang SIM a/c bulan 10 matinya , dan diperpanjang bulan 6 sekarang apa bisa 2. siap terima kasih | H13: 1. bisa pak, dan masa berlaku mengikuti tgl pendaftaran perpanjangan SIM 2. terima kasih kembali
A14: 5 | B14: 45449 | C14: FACEBOOK | D14: Heryanto Frizka | E14: SAMSAT | G14: 1. Surabaya pusat dimana yg terdekat 2. makasih infonya | H14: 1. bisa di samsat payment point taman budaya cak durasim 2. terima kasih kembali
A15: 6 | B15: 45449 | C15: FACEBOOK | D15: Agung Wida Ngalam Greasetrap | E15: SAMSAT | G15: 1. Untuk PAJAK RanMor 5th an/ sekalian MUTASI luar kota bisa? Klu tidak bisa,..Samsat Tandes Besok Sabtu tgl 8 pa buka? 2. thanks infonya | H15: 1.samsat keliling hanya melayani pembayaran dan pengesahan pajak tahunan, hari sabtu buka mulai pukul 08.00 - 11.00 WIB, trims 2. terima kasih kembali
A16: 7 | B16: 45449 | C16: FACEBOOK | D16: Kendiel Joko | E16: SIM | G16: 1. Blitar gak pernah ada 2. sim keliling ye | H16: 1. blitar kab hari ini 7 Juni 2024 ada di Halaman Kec Gandusari dan besok 8 Juni 2024 ada di Halam Kantor Kec Garum
A17: 8 | B17: 45449 | C17: FACEBOOK | D17: Febrina Prameswari | E17: SIM | G17: 1. Utk SIM keliling di Sidoarjo apakah memakai kuota? Per hari berapa kuota? Mohon info 2. baik Terimakasih infonya karena suami pernah datang ditolak alasannya kuotanya habis pdhl belum jam 12 siang. | H17: 1. tanpa kuota,mbak
A18: 9 | B18: 45449 | C18: WHATSAPP | D18: +62 818-578-481 | E18: SAMSAT | G18: 1.Selamat pagi Mohon info untuk pengurusan kendaraan baru dari dealer, syarat pengurusannya apa aja? Dan apa kendaraannya perlu dibawa ke polda? | H18: 1. selamat pagi, surat faktur ktp dan kendaraan nya dibawa ke polda
A19: 10 | B19: 45449 | C19: WHATSAPP | D19: +62 899-3422-813 | E19: SAMSAT | G19: 1. Siang pak 2. Maaf. Apakah bisa tanya untuk stnk sama BPKB motor saya yang kemarin bulan januari balik nama. Apakah sudah selesai apa belum pak?? 3. nopol S 3812 TU 4. iya pak 5. Siang pak | H19: 1. siang 2. sebentar ya pak saya bantu cekkan 3. sudah selesai pak dan sudah diambil 4. kendaraan atas nama AKMAD SUHADI
A20: 11 | B20: 45451 | C20: WHATSAPP | D20: 62 896-7875-0699 | E20: LAIN-LAIN | G20: 1. Selamat siang, Mau tanya untuk jam operasional ditlantas polda jatim jam berapa sampai jam berapa ya? 2. Terimakasih | H20: 1. jam 08.00 - 12.00 ya pak/bu
A21: 12 | B21: 45451 | C21: WHATSAPP | D21: +62 823-3565-2495 | E21: SAMSAT | G21: 1. Selamat malam 2. Mohon maaf mau menanyakan untuk bpkb setelah pergantian plat kira2 bisa di ambil kapan ya ? 3. Dengan kendaraan nopol S 6985 SM 4. Mojokerto Kota 5. Oh yasudah terima kasih respon nya 6. Ohya terima kasih infonya. Berarti belum bisa diambil yaa | H21: 1. untuk pergatian platnya berada di samsat mana ya pak/bu ? 2. bisa langsung ditanyakan ke pihak terkait ya pak, di samsat mojokerto kotanya 3. setelah kita bantu cek bpkb belum tercetak atas nama TANYA EDI SAPUTRI
A22: 13 | B22: 45453 | C22: FACEBOOK | D22: Taufik | E22: SIM | G22: 1. SIM keliling gresik kok gak ada 2. Siap | H22: 1. mhn maaf masih blm beroperasi
... A41: 32 | B41: 45455 | C41: FACEBOOK | D41: Kiyomizu Kudo | E41: SIM | G41: 1. Saran sih Pak, di post nya semingu/ 3 hari sebelum hari H, biar bisa prepare cuti kerja dll... Thanks Pak | H41: 1. terima kasih sarannya
A42: 1 | B42: 45474 | C42: FACEBOOK | D42: Susanto | E42: SIM | F42: REGIDENT | G42: 1. Luar kota bisa ta pak | H42: 1. Bisa untuk Sim A & C
A43: 2 | B43: 45477 | C43: WHATSAPP | D43: +62 895-0808-4107 | E43: SIM | F43: REGIDENT | G43: 1. Sekarang jadwal yg pasti dimana pak sim kelilingnya | H43: 1. Di lippo/ramayana krian/pondok tjandra sidoarjo
A44: 3 | B44: 45478 | C44: FACEBOOK | D44: Fahri Khusaini | E44: SIM | F44: REGIDENT | G44: 1. Apakah jadwal ini berlaku sampai besok | H44: 1. untuk jadwal kami hadir tiap hari
A45: 4 | B45: 45480 | C45: WHATSAPP | D45: +62 896-7927-2792 | E45: SIM | F45: REGIDENT | G45: 1. untuk besok senin sim keliling dimana ya pak? 2. Untuk wilayah sidoarjo 3. Dari jam berapa pak? 4. Terimksh pak | H45: 1. pondok candra dan parkir lippo mall kak 2. pkl 08.00 - 12.00
A46: 5 | B46: 45481 | C46: WHATSAPP | D46: +62 819-9955-6408 | E46: SIM | F46: REGIDENT | G46: 1. Min mau tanya, besok perpanjang sim di pondok candra buka apa tidak ya? | H46: 1. buka kak 2. pkkl 08.00 - 12.00
A47: 6 | B47: 45481 | C47: WHATSAPP | D47: +62 878-5955-8191 | E47: SIM | F47: REGIDENT | G47: 1. Selamat pagi, apakah hari ini ada jadwal sim keliling di ramayana krian sidoarjo ? Terima kasih | H47: 1. pagi mas 2. ada sampai dengan pkl 12.00
A48: 7 | B48: 45481 | C48: FACEBOOK | D48: Fahri Khusaini | E48: SIM | F48: REGIDENT | G48: 1. Untuk kuota maksimal brp | H48: 1. tidak ada kuota maksimal ya pak, tapi disarankan untuk datang lebih awal
A49: 8 | B49: 45481 | C49: FACEBOOK | D49: Wahyu Prasetyo | E49: SIM | F49: REGIDENT | G49: 1. Surabaya apa bisa ndan | H49: 1. bisa
A50: 9 | B50: 45486 | C50: WHATSAPP | D50: +62 811-3237-513 | E50: SIM | F50: REGIDENT | G50: 1. Selamat malam 2. Mohon informasi untuk tes kesehatan dan psikologi utk perpanjangan SIM di Sidoarjo jika dilakukan di Mall Lippo Plaza Sidoarjo? | H50: 1. bisa kak
A51: 10 | B51: 45487 | C51: WHATSAPP | D51: +62 822-2895-8002 | E51: SIM | F51: REGIDENT | G51: 1. permisi mengenai perpanjangan sim keliling disidoarjo ada dimana untuk tanggal 15juli | H51: 1. bisa di cek di fb instagram kita ya pak
A52: 11 | B52: 45487 | C52: WHATSAPP | D52: +62 895-0932-1437 | E52: SIM | F52: REGIDENT | G52: 1. Assalamualaikum Mohon maaf.. Biaya untuk perpanjangan SIM C sekarang berapa2. Syarat perpanjangan SIM C sekarang apa saja..3. Domisili Tanggulangin Sidoarjo | H52: 1. Biaya Perpanjangan SIM C: Rp 75.000 untuk perpanjangan SIM C. Biaya Tambahan (Opsional): Surat Keterangan Sehat: Rp 25.000 - Rp 100.000 (biaya ini bervariasi tergantung pada klinik atau rumah sakit yang mengeluarkan surat keterangan sehat).
A53: 12 | B53: 45489 | C53: WHATSAPP | D53: +62 857-4876-5151 | E53: SIM | F53: REGIDENT | G53: 1. Selamat Pagi 2. Mohon info jadwal SIM keliling wilayah Sidoarjo 3. Terimakasih | H53: 1. bisa di cek di fb instagram kita ya pak
... A71: 1 | B71: 45506 | C71: WHATSAPP | D71: +62 823-3892-9663 | E71: SIM | F71: REGIDENT | G71: 1. Selamat siang, perkenalkan saya ifa, Mohon ijin, info jadwal simling Surabaya...? Terimakasih sebelumnya | H71: 1. untuk sementara masih belum ada kak, segera di update lebih lanjut
A72: 2 | B72: 45506 | C72: WHATSAPP | D72: +62 888-0487-2750 | E72: LAIN-LAIN | G72: 1. Lapor HP HILANG 2. Apakah bisa dibantu untuk menemukan | H72: 1. bisa langsung menuju ke spkt terdekat dulu pak
A73: 3 | B73: 45506 | C73: WHATSAPP | D73: +62 895-3525-65028 | E73: LAIN-LAIN | F73: LAIN-LAIN | G73: 1. Test. 2. Enggak pak,saya hanya test saja. | H73: 1. ada yang bisa dibantu?
A74: 4 | B74: 45506 | C74: WHATSAPP | D74: +62 823-3155-8693 | E74: SIM | F74: REGIDENT | G74: 1. Selamat sore pak,,, mohon ijin tanya untuk perpanjangan SIM C warga Jawa tengah di Surabaya apakah bisa dilakukan di BG junction? 2. Hari Minggu buka ya kak? 3. Terimakasih banyak kak atas infonya,,, 🙏🙏🙏 | H74: 1. bisa kak asalkan persyaratan lengkap 2. Untuk hari minggu tutup pak 3. Hari senin - sabtu buka pak
A75: 5 | B75: 45506 | C75: WHATSAPP | D75: +62 813-3646-8401 | E75: SIM | F75: REGIDENT | G75: 1. Malam...dolor jadwal sim keliling wilayah krian 2. Mohon di infoo 3. Ok makasih | H75: 1. gambar jadwal simling sidoarjo, 3 Agustus 2024
...

Sheet Sheet3
B1: [09:36, 01/06/2025 | C1: +62 856-3230-700 | D1: Selamat pagi
B2: [09:37, 01/06/2025 | C2: +62 856-3230-700 | D2: Untuk perpanjang SIM A di Kahuripan nirwana,ada syarat kesehatan dokter SM psikologi,itu bisa dilakukan disana atau mencari sendiri sebelum perpanjangan ya?
B3: [19:44, 01/06/2025 | C3: RTMC JATIM | D3: selamat malam kak maaf tadi ada trobel sistem jadi lama balas nya
B4: [19:44, 01/06/2025 | C4: RTMC JATIM | D4: untuk kesehatan sm psikologi ada di tempat kak
B5: [20:13, 01/06/2025 | C5: +62 856-3230-700 | D5: Jadi yg perlu disiapkan dr rumah apa aja kak?
B6: [20:14, 01/06/2025 | C6: RTMC JATIM | D6: itu kak syarat nya sim yg akan perpanjang dan ktp
B7: [20:14, 01/06/2025 | C7: +62 856-3230-700 | D7: Oh ya untuk SIM habis tgl 11 kak,besok sudah bisa perpanjang kan ya?
B8: [20:14, 01/06/2025 | C8: RTMC JATIM | D8: sudah bisa kak
B9: [20:15, 01/06/2025 | C9: +62 856-3230-700 | D9: Kak yg di Kahuripan nirwana g ada ya?
B10: [20:15, 01/06/2025 | C10: +62 856-3230-700 | D10: Diganti di Lippo?
B11: [20:16, 01/06/2025 | C11: RTMC JATIM | D11: ada kak
B12: [20:17, 01/06/2025 | C12: RTMC JATIM | D12: lippo dari polda kalau di kahuripan dari polresta sidoarjo
... B23: [20:22, 01/06/2025 | C23: RTMC JATIM | D23: tidak harus kak
B24: [20:22, 01/06/2025 | C24: RTMC JATIM | D24: kalau awal bulan seperti ini kebanyakan rame kak | L24: +62 811-3070-2826
B25: [20:23, 01/06/2025 | C25: RTMC JATIM | D25: bawah foto copy ktp sm sim nya masing² 3 lembar kak biar tidak bingung cari foto copy lg | L25: +62 822-6558-9819
B26: [20:26, 01/06/2025 | C26: +62 856-3230-700 | D26: Bisa diinfo lokasi yg di pocan? | L26: +62 822-5765-2986
B27: [20:45, 01/06/2025 | C27: RTMC JATIM | D27: ruko palm kak | L27: +62 878-5808-6000
B28: belakang giant yg sudah tutup | L28: +62 895-1590-0725
B29: [20:47, 01/06/2025 | C29: +62 856-3230-700 | D29: Makasih kak infonya ❤️ | L29: +62 822-3421-0313
B30: [20:48, 01/06/2025 | C30: RTMC JATIM | D30: sama sama kak | L30: +62 897-9799-904
B31: [20:48, 01/06/2025 | C31: RTMC JATIM | D31: besok sendiri apa sm suami? | L31: +62 878-5392-1505
B32: [20:48, 01/06/2025 | C32: RTMC JATIM | D32: saran saya di temani suami kak takut nya anak nya rewel pas saat tes psiko atau kesehatan | L32: +62 822-3481-9676
B33: [20:49, 01/06/2025 | C33: RTMC JATIM | D33: atau bawa saudara | L33: +62 823-3554-1927
B34: [20:49, 01/06/2025 | C34: +62 856-3230-700 | D34: Sama 2 lansia dan 2 bayi 5 bulan 🤭 | L34: +62 813-3612-5956
B35: [20:49, 01/06/2025 | C35: +62 856-3230-700 | D35: Siap kak
B36: [20:49, 01/06/2025 | C36: RTMC JATIM | D36: oh ya kak alhamdulillah kalau ada kakek nenek nya
B37: [20:50, 01/06/2025 | C37: +62 856-3230-700 | D37: Iya kak,semoga g antri banyak besok
B38: [20:50, 01/06/2025 | C38: +62 856-3230-700 | D38: Makasih kak,met istirahat ❤️
B39: [20:51, 01/06/2025 | C39: RTMC JATIM | D39: yaa semoga kak
B40: kadang juga kasian kalau bawa bayi itu 🥹
B41: [20:51, 01/06/2025 | C41: RTMC JATIM | D41: terimakasih kak 🥰

Sheet Copy of REKAP
A1: NO | B1: PERTANYAAN | C1: JAWABAN
A2: 1 | B2: - Selamat pagi Bapak/Ibu, saya Rizki dari Surabaya, mohon izin bertanya/info, untuk pengurusan kartu induk BPKB yang hilang perlu waktu berapa lama ya? Atau adakah nomor/media/kanal yang bisa dihubungi untuk bertanya karena saya cari melalui internet/medsos sepertinya belum ada? Mohon bantuannya bapak/ibu. Terimakasih🙏🏻🙏🏻 | C2: - bisa dibantu nopolnya? kami bantu cek
A3: 2 | B3: - Assalamualaikum pak selamat siang- Saya mau ngambil stnk tanpa harus di sidang gimana caranya?- Ini tandanya polsek gubeng,Tapi malah di suruh sidang di Sukomanunggal.- Katanya bapak nya saya di suruh (ngurus atau disidang)Nah saya pilih di urus pak biar cepat dan clear. | C3: - walaikumsalam selamat siang- ada yg bisa kami bantu- Wilayah mana pak/bu- ada no tilangnya kita bantu cek terlebih dahulu- silahkan datang di satpas colombo untuk meminta kode briva di kantor tilang polrestabes surabaya
A4: 3 | B4: -Selamat pagi-Perkenalkan saya Herlambang,-Mohon bantuan petunjuknya Bapak/Ibu, untuk persyaratan penerbitan Surat Rekomendasi Polda Jatim, untuk keperluan pendaftaran STNK & BPKB kendaraan di kantor Samsat daerah Jawa Timur.-Domisili Banyuwangi Pak-Namun saat ini kendaraan berada di Bekasi, Jawa Barat Pak/Bu-Baik terimakasih atas informasinya, Izin bertanya apakah persyaratan penerbitan Surat Rekomendasi bisa disampaikan melalui jasa pengiriman dokumen (Pos) atau melalui email Pak/Bu?--Karena saat ini saya tinggal di bekasi namun data KTP masih beralamat di Banyuwangi. Terimakasih🙏-Baik Bapak/Ibu terimakasih atas informasinya🙏-Sehubungan dengan persyaratan yang dimohonkan untuk penerbitan surat Rekomendasi Polda Jatim, ada persamaan berkas yang disampaikan untuk penerbitan BPKB dari kantor Samsat Banyuwangi sesuai persyaratan terlampir Pak/Bu-Mohon izin bertanya kembali Pak/bu apakah ketika pengajuan permohonan penerbitan surat rekomendasi Polda Jatim Dokumen Asli hanya untuk ditunjukkan dan yang disampaikan untuk surat rekomendasi adalah dokumen duplikat/copy Bapak/Ibu? | C4: -pemenang lelang domisili mana pak/bu-atau bisa difotokan dokumen lelalng nya-mohon maaf tidak bisa, dikarenakan butuh berkas asli, dan apabila dikirim melalui POS dikhawatirkan tidak terkirim, trims-Untuk surat yg dibawa ke polda harus asli pak/bu
A5: 5 | B5: Untuk Sidoarjo dimana aja untuk bayar pajak spdh | C5: silahkan datang di samsat corner lotte mart,samsat keliling kota,samsat keliling krian,samsat payment point wadung asri,samsat payment point samsat lama,samsat payment point bank jatim taman, samsat payment point puspa agro terima kasih
A6: 6 | B6: 1. Bayar pajak kendaraan tanpa ktp pemilik pertama apakah bisa???2.Siap 🙏🙏🙏 | C6: mohon maaf tidak bisa, apabila sudah berpindah tangan bisa balik nama di samsat asal, terima kasih
A7: 4 | B7: -Selamat siang, betul dengan akun whatsapp polsek tegalsari surabaya?-Mohon maaf, adakah kontak whatsapp polsek tegalsari yang bisa saya hubungi Pak/Bu?-Saya ingin menanyakan perihal kerabat saya yg terakhir kali infonya sedang berada di polsek tegalsari Surabaya🙏🏻--Baik, terimakasih bantuannya Pak/Bu 🙏🏻-Baik, untuk nomor whatsapp nya belum ada ya Pak/Bu? | C7: -dengan rtmc polda jatim-Ada yg bisa dibantu-Mhn waktu-izin pak/bu ini untuk nomor dari polsek tegal sari 031 5341052-untuk sementara nomor dari polsek tegalsari hanya ini saja
A8: 7 | B8: Maaf, bs untuk upgrade SIM A ke B1 | C8: mohon maaf tidak bisa sim keliling hanya melayani perpanjangan sim A dan C saja, terima kasih
A9: 8 | B9: 1. Kalau perpanjang SIM maksimal berapa hari sebelum masa berlaku2. ini berlaku seluruh Jawa timur | C9: 1. sebelum masa berlaku habis2. iya pak
A10: 1 | B10: 1. SIM saya surabaya, sekarang KTP Sidoarjo. Mau memperpanjang SIM. Mohon pencerahan dari ditlantas Polda.Terima kasih.2.Terima kasih pencerahannya. | C10: 1. kalau SIM A dan C bisa diperpanjang dimana saja mas, asal SIM tersebut belum kadaluarsa dan mengikuti KTP alamat baru
A11: 2 | B11: 1. Apakah di sim keliling di sediakan tempat psikologi dan surat kesehatan | C11: 1. sudah tersedia
A12: 3 | B12: 1. mutasi masuk apakah bisa langsung ke samsat tujuan?2. mobil plat N Malang masuk ke Surabaya samsat Kedung Cowek dan mobil plat Bandar Lampung masuk ke Surabaya samsat Kedung Cowek ndan, mohon pencerahannya, terima kasih3.sudah tidak perlu cabut berkas lagi di samsat asal ya ndan?4. siap, terima kasih infonya ndan 🙏🙏🙏 | C12: 1.dari samsat mana kemana pak2. apabila dari plat N langsung ke samsat tujuan namun untuk plat luar wilayah jawa timur ke polda terlebih dahulu, trims3. tetap cabut di samsat asal pak
A13: 4 | B13: 1. Perpanjang SIM a/c bulan 10 matinya , dan diperpanjang bulan 6 sekarang apa bisa2. siap terima kasih | C13: 1. bisa pak, dan masa berlaku mengikuti tgl pendaftaran perpanjangan SIM2. terima kasih kembali
... A196: 59 | B196: 1. Siang admin rtmc jatim2. Untuk SIM yg sudah kadaluwarsa 13 hari apakah masih bisa perpanjangan?3. Karena saya pikir kedaluwarsa sesuai tanggal lahir, ternyata tanggal pembaruan terakhir4. Terimakasih Informasinya | C196: 1. tidak bisa pak/bu bila masa sim berlaku habis maka diharuskan membuat sim baru
A197: 66
A198: 67
A199: 68
A200: 1 | B200: 1. Selamat pagi2. Info jadwal SIM di Surabaya | C200: 1. untuk sim keliling surabaya belum ada jadwalnya pak/bu sementara hanya di sidoarjo saja
A201: 2 | B201: 1.Selamat siang pak Saya mau nanya Sim nganjuk apa bisa di perpanjang di sidoarjo ?2. Persyaratannya apa saja pak?3. Siap pak besok berangkat ke lippo | C201: 1. bisa pak/bu asalkan sudah e-ktp2. 📝 Persyaratan Perpanjangan SIM:- KTP asli- SIM asli- Fotokopi KTP 2 lembar- Fotokopi SIM 2 lembar- Surat Keterangan Sehat⚠️ Catatan Penting:- Layanan hanya untuk perpanjangan SIM A dan C.- Tidak melayani penerbitan SIM baru.
A202: 3 | B202: 1. Selamat siang. Mohon informasinya pelayanan tutup jam berapa2. Kami dari kota Mojokerto mau urus berkas mutasi kendaraan kami3. Siap terima kasih 🙏🙏4. Mohon ijin Bapak menayangkan apakah hari Sabtu buka untuk pelayanan.petunjuk Terimakasih 🙏🙏 | C202: 1. RTMC JATIM: jam 12.00 pak/bu2. buka pak/bu pelayanan sampai jam 11.00
A203: 4 | B203: 1. Selamat malam2. SiapTerima kasih infonya 🙏🙏🙏 | C203: 1. Mohon ijin komandan untuk jadwal SIM keliling per tanggal 2 Oktober 2024 di laksanakan di mana ya ??🙏🙏🙏 1. Untuk Sim keliling daerah sidoarjo berada di sini pak/bu 1. LIPPO PLAZA 2. PONDOK TJANDRA 3. RAMAYANA KRIAN Jam Pelayanan Mulai Pukul 08.00 - 12.00 Di hari Senin sampai hari Kamis bila hari jum at dan sabtu jam pelayanan dimulai pukul 08.00 - 11.00
A204: 5 | B204: 1. Halo min2. Minta info jadwal sim keliling di Ramayana Krian. Hari apa ya3. Untuk biaya perpanjang SIM C berapa ya?4. Terimakasih | C204: 1. Untuk SIM keliling daerah Sidoarjo berada di sini, Pak/Bu:LIPPO PLAZAPONDOK TJANDRARAMAYANA KRIANJam pelayanan mulai pukul 08.00 - 12.00 di hari Senin sampai hari Kamis. Bila hari Jumat dan Sabtu, jam pelayanan dimulai pukul 08.00 - 11.002. Untuk PNBP SIM A perpanjangan: 80.000Untuk PNBP SIM C perpanjangan: 75.000
A205: 6 | B205: 1. Selamat sore mohon maaf mengganggu saya Pak Zaenudin mohon info jadwal utk SIM keliling tanggal 04 Oktober 2024🙏 2. Wilayah Sidoarjo🙏 3. Ok siap Bapak/Ibu terimakasih untuk informasinya 🙏🙏 4. Selamat malam🫡 | C205: 1. Untuk SIM keliling daerah Sidoarjo berada di sini, Pak/Bu: - LIPPO PLAZA - PONDOK TJANDRA - RAMAYANA KRIAN Jam pelayanan mulai pukul 08.00 - 12.00 di hari Senin sampai hari Kamis. Bila hari Jumat dan Sabtu, jam pelayanan dimulai pukul 08.00 - 11.00
A206: 7 | B206: 1. Mohon maaf untuk SIM kelilingnya untuk hari Minggu di daerah Sidoarjo apakah ada 2. Untuk surat kesehatannya dibuat sekalian di SIM keliling bisa apa enggak ya 3. Dan bila bisa, biayanya berapa 4. Biayanya berapa ya 5. Biaya kesehatan sama psikologinya di situ bayar berapa ya 6. Itu tes kesehatan aja atau sudah sama psikologi 7. Oh.. Ok.. Terimakasih atas informasinya | C206: 1. Untuk hari Minggu, pelayanan libur ya, Pak/Bu 2. Bisa, Pak/Bu 3. Untuk PNBP SIM A perpanjangan: 80.000 Untuk PNBP SIM C perpanjangan: 75.000 CATATAN: Biaya kesehatan dan psikologi di luar PNBP Polri 4. Mohon maaf, Pak/Bu. Dikarenakan kesehatan sama psikologi di luar wewenang kami, jadi kami tidak bisa memutuskan untuk biaya tes kesehatan dan psikologi 5. Tetapi biasanya untuk harga include rentang harga 250 - 300 ribu, Pak/Bu 6. Sudah semua include kesehatan, psikologi, dan biaya perpanjang SIM 7. Terimakasih kembali
A207: 8 | B207: 1. Pak mau tanya 2. Kalau SIM Probolinggo diperpanjang di Sidoarjo apakah bisa atau tidak ya? 🙏🏼🙏🏼🙏🏼 | C207: 1. Bisa, Pak/Bu, asalkan sudah e-KTP
A208: 9 | B208: 1. Assalamualaikum kak, perpanjangan SIM C kena biaya berapa ya | C208: 1. Untuk PNBP SIM A perpanjangan: 80.000 Untuk PNBP SIM C perpanjangan: 75.000 CATATAN: Biaya kesehatan dan psikologi di luar PNBP Polri
A209: 10 | B209: 1. Selamat sore 🙏 Mohon ijin bertanya Untuk sistem antrian seperti apa ya? Dan untuk surat sehat apakah boleh dari klinik mana saja? 2. Terima kasih 🙏 3. Baik, terima kasih banyak informasinya 🙏 | C209: 1. Untuk sistem antrian langsung, Pak/Bu. Untuk surat kesehatan bisa dari luar, Pak/Bu
A210: 11 | B210: 1. Mau tanya untuk SIM keliling daerah Pondok Candra mana nya ya? | C210: 1. Di depan Bank BCA Pocan ya, Pak/Bu
A211: 12 | B211: 1. Siang pak/bu 2. Mau tanya perpanjangan SIM C Sidoarjo, surat keterangan sehatnya ngurusnya di mana? 3. Oh ok trims 4. Siang pak/bu mau tanya SIM C mau habis kurang 2 minggu lagi, apakah bisa diurus? | C211: 1. Di tempat perpanjangan SIM cek kesehatan sudah tersedia, Pak/Bu 2. Bisa, Pak/Bu
... A303: 4 | B303: 1. Selamat siang mau izin tanya untuk sekarang SIM keliling apa masih beroperasional ya terima kasih ? | C303: 1. masih pak/bu
A304: 5 | B304: 1. Info sim corner sidoarjo 2. Knapa kamis pindah ke porong 3. Apa hari ini sim keliling buka | C304: 1. Untuk SIM keliling daerah Sidoarjo berada di sini pak/bu: - LIPPO PLAZA - PONDOK TJANDRA - RAMAYANA KRIAN Jam Pelayanan: - Senin - Kamis: 08.00 - 12.00 - Jumat & Sabtu: 08.00 - 11.00 2. Tidak ada pindah ke Porong pak 3. Buka bapak/ibu | F304: WHATSAPP | G304: =COUNTIF(#REF!,F304) -> 0 | I304: SAMSAT | J304: =COUNTIF(#REF!,I304) -> 0 | L304: REGIDENT | M304: =COUNTIF(#REF!,L304) -> 0
A305: 6 | B305: Selamat siang. Izin bertanya, apa benar jika ingin perpanjang SIM A/C di SIM keliling Sidoarjo harus H-3 sebelum masa berlakunya habis? | C305: 1. Bisa dilakukan 2 minggu sebelum masa SIM habis pak/bu, hanya saja lebih diprioritaskan bila masa SIM sudah mendekati habis. | F305: FACEBOOK | G305: =COUNTIF(#REF!,F305) -> 0 | I305: SIM | J305: =COUNTIF(#REF!,I305) -> 0 | L305: GAKKUM | M305: =COUNTIF(#REF!,L305) -> 0
A306: 7 | B306: 1. Selamat siang pak.Mau tanya untuk besok perpanjangan sim di lippo plaza apa ada pak? | C306: 1. ada pak/bu | F306: INSTAGRAM | G306: =COUNTIF(#REF!,F306) -> 0 | I306: LAKA | J306: =COUNTIF(#REF!,I306) -> 0 | L306: PJR | M306: =COUNTIF(#REF!,L306) -> 0
A307: 8 | B307: 1. Halo mau tanya apakah bisa melakukan tes kesehatan dan psikologi di tempat sim keliling untuk perpanjangan sim di sidoarjo? | C307: 1. bisa pak/bu | F307: X/TWITTER | G307: =COUNTIF(#REF!,F307) -> 0 | I307: TILANG | J307: =COUNTIF(#REF!,I307) -> 0 | L307: KAMSEL | M307: =COUNTIF(#REF!,L307) -> 0
A308: 9 | B308: 1. Selamat pagi. Mau tanya, untuk sim keliling di lippo, buka jam berapa ya? | C308: 1. buka mulai pukul 08.00 - 12.00 | G308: =SUM(G304:G307) -> 0 | I308: LAIN-LAIN | J308: =COUNTIF(#REF!,I308) -> 0 | L308: LAIN-LAIN | M308: =COUNTIF(#REF!,L308) -> 0
A309: 10 | B309: 1. Dimn diadakan pak?2. Klu SIM keliling bisa bikin baru pak? | C309: 1. Persyaratan Perpanjangan SIM:KTP asliSIM asliFotokopi KTP 2 lembarFotokopi SIM 2 lembarSurat Keterangan Sehat2. Tidak bisa pak/bu.3. Hanya melayani perpanjangan SIM A dan C saja | J309: =SUM(G303:G307) -> 0
A310: 11 | B310: 1. Selamat malam pak 2. Mau menanyakan soal perpanjangan SIM, untuk surat kesehatannya itu minta di institusi resmi dimana pak? 3. Terima kasih🙏 4. Terima kasih atas informasinya 5. Kalo di Lippo Plaza di sebelah mana pak/bu? | C310: 1. Bisa langsung datang ke lokasi ya pak/bu, sudah tersedia untuk cek kesehatan dan tes psikologi. 2. Di dalam mall ya pak.
A311: 12 | B311: 1. Assalamualaikum, selamat pagi Bapak/Ibu. Mohon maaf mau bertanya untuk mengurus NRKB Pilihan di Polda Jatim bisa menghubungi kemana ya Pak/Bu? Terima kasih 2. Baik.. terima kasih banyak atas infonya 🙏🏻 | C311: 1. Bisa menghubungi 085755983591 / 085730002090.
A312: 13 | B312: Selamat pagi Mau tanya, surat keterangan sehat dari istitusi kesehatan resmi itu bisa di dapat dimana ? | C312: bisa langsung di dapat ditempat ya kak, sudah tersedia untuk cek kesehatan dan tes psikologi
A313: 14 | B313: 1. Selamat pagi pak, mau menanyakan untuk SIM keliling ke Krian kapan ada jadwalnya lagi pak? Terima kasih infonya 🙏2. Baik terimakasih pak | C313: 1. Untuk SIM keliling daerah Sidoarjo berada di sini pak/bu: - LIPPO PLAZA - PONDOK TJANDRA - RAMAYANA KRIAN 2. Jam Pelayanan: - Senin - Kamis: 08.00 - 12.00 - Jumat & Sabtu: 08.00 - 11.00 Persyaratan Perpanjangan SIM: - KTP asli - SIM asli - Fotokopi KTP 2 lembar - Fotokopi SIM 2 lembar - Surat Keterangan Sehat
...

Sheet JENIS
F1: SUBDIT
B2: JENIS | D2: PERTANYAAN | F2: REGIDENT
B3: WHATSAPP | D3: SAMSAT | F3: GAKKUM
B4: FACEBOOK | D4: SIM | F4: PJR
B5: INSTAGRAM | D5: LAKA | F5: KAMSEL
B6: TIKTOK | D6: ETLE | F6: LAIN-LAIN
D7: LAIN-LAIN
D8: STNK
D9: BPKB

Sheet Sheet4
B3: WHATSAPP | C3: 22 | G3: SAMSAT | H3: 12 | L3: REGIDENT | M3: 29 | Q3: WHATSAPP | R3: 128 | U3: SAMSAT | V3: 7 | Z3: REGIDENT | AA3: 145
B4: FACEBOOK | C4: 4 | G4: SIM | H4: 20 | L4: GAKKUM | M4: 5 | Q4: FACEBOOK | R4: 3 | U4: SIM | V4: 138 | Z4: GAKKUM | AA4: 4
B5: INSTAGRAM | C5: 10 | G5: LAKA | H5: 0 | L5: PJR | M5: 0 | Q5: INSTAGRAM | R5: 25 | U5: LAKA | V5: 0 | Z5: PJR | AA5: =COUNTIF(REKAP!$F$428:$F$444,Z5) -> 0
B6: X/TWITTER | C6: =COUNTIF(REKAP!$C$428:$C$444,B6) -> 0 | G6: TILANG | H6: 4 | L6: KAMSEL | M6: 0 | Q6: X/TWITTER | R6: =COUNTIF(REKAP!$C$428:$C$444,Q6) -> 0 | U6: TILANG | V6: 4 | Z6: KAMSEL | AA6: 0
C7: =SUM(C3:C6) -> 36 | G7: LAIN-LAIN | H7: 0 | L7: LAIN-LAIN | M7: 0 | R7: =SUM(R3:R6) -> 156 | U7: LAIN-LAIN | V7: 9 | Z7: LAIN-LAIN | AA7: 9
H8: =SUM(H3:H7) -> 36 | M8: =SUM(M3:M7) -> 34 | V8: =SUM(V3:V7) -> 158 | AA8: =SUM(AA3:AA7) -> 158
A34: JAN - MEI
A35: WHATSAPP | B35: 177 | D35: SAMSAT | E35: 23 | G35: REGIDENT | H35: 188
A36: FACEBOOK | B36: 20 | D36: SIM | E36: 165 | G36: GAKKUM | H36: 17
A37: INSTAGRAM | B37: =COUNTIF(REKAP!$C$375:$C$523,A37) -> 18 | D37: LAKA | E37: =COUNTIF(REKAP!$E$375:$E$523,D37) -> 0 | G37: PJR | H37: =COUNTIF(REKAP!$F$375:$F$523,G37) -> 0
A38: X/TWITTER | B38: =COUNTIF(REKAP!$C$375:$C$523,A38) -> 0 | D38: TILANG | E38: 17 | G38: KAMSEL | H38: 0
B39: =SUM(B35:B38) -> 215 | D39: LAIN-LAIN | E39: 19 | G39: LAIN-LAIN | H39: 19
E40: =SUM(E35:E39) -> 224 | H40: =SUM(H35:H39) -> 224

Sheet Sheet5
A1: NO | B1: TANGGAL | C1: MEDIA ADUAN | D1: NAMA / NOMOR | E1: JENIS | F1: SUBDIT | G1: PERTANYAAN | H1: JAWABAN
A2: 1 | B2: 46024 | C2: WHATSAPP | D2: +62 856-7649-513 | E2: SIM | F2: REGIDENT | G2: 1. Saya ingin bertanya tentang ... perpanjang SIM hari Jumat 2 Desember apakah sudah beroperasi kembali SIM keliling Ramayana Ciplaz/terminal pasar Porong. Terimakasih 2. Baik saya tunggu informasi 3. Min, bagaimana? apakah hari ini SIM keliling sudah beroperasi kembali di Ramayana Ciplaz Sidoarjo? terimakasih | H2: 1. mohon waktu ya kak saya tanyakan untuk wilayah sidoarjo 2. sdh kak
A3: 2 | B3: 46024 | C3: WHATSAPP | D3: +62 899-8989-602 | E3: SIM | F3: REGIDENT | G3: 1. Selamat malam, Besok SIM keliling Sidoarjo buka ga min? | H3: 1. buka kak
A4: 3 | B4: 46024 | C4: WHATSAPP | D4: +62 812-3598-421 | E4: SAMSAT | F4: REGIDENT | G4: 1. Mohon info, saya akan balik nama kendaraan R4 utk bayar pajak, tp ternyata di samsat asal (Gresik) infonya perlu buka blokir ke Polda Jatim tp sebelumnya ke BCA Finance dulu. Stl ke BCA, infonya tidak ada data plat no kendaraan saya di data BCA. Lalu bagaimana saya mengurus buka blokir ke Polda Jatim kalau surat pengantar dari Bank tidak ada ? 2. Baik, terima kasih infonya 3. Mohon info dokumen apa saja yang perlu dibawa ? 4. surat keterangan dri leasing ------> ini yg nggak ada, saya minta ke BCA Finance sesuai info dr Samsat Gresik infonya dari BCA Finance nggak ada Lalu bagaimana ? BPKB, STNK, Kuitansi pembelian ada semua Cek fisik kendaraan, mesin, rangka di Samsat Gresik juga sdh ada | H4: 1. mnta data di polda gedung rtmc bagian blokir 2. sma2 kak 3. surat keterangan dri leasing,bpkb asli,stnk asli 4. mnta data di bagian blokir polda gedung rtmc,untuk mnta data ikut leasing bca mna 5. untuk kendaraan kakak 6. betul kak
A5: 4 | B5: 46024 | C5: WHATSAPP | D5: +62 822-3130-3326 | E5: SIM | F5: REGIDENT | G5: 1. Saya ingin bertanya tentang perpanjangan SIM hari ini apa bisa 2. Expired kuu tgl 26 Januari apa bisa ? | H5: 1. bisa bsk kak jm 8.00 - 12.00 wib 2. bisa H-3 kak untuk perpanjangan
A6: 5 | B6: 46024 | C6: WHATSAPP | D6: +62 895-3417-64793 | E6: SIM | F6: REGIDENT | G6: 1. halo ka untuk pelayanan perpanjangan sim di taman bungkul apakah ada ya? bukanya jam berapa kalo boleh tau? | H6: 1. program simanis di tmn bungkul jumat,sabtu jm18.00 - 21.00 wib
A7: 1 | B7: 46026 | C7: WHATSAPP | D7: +62 857-3343-6300 | E7: SAMSAT | F7: REGIDENT | G7: 1. Selamat siang, Admin. Mohon izin bertanya terkait prosedur permohonan Nomor Registrasi Kendaraan Bermotor (NRKB) Pilihan atau pelat nomor cantik. Apa saja persyaratan dokumen yang harus disiapkan dan bagaimana alur pengurusannya? Terima kasih atas informasinya. 2. Mohon informasinya mengenai jadwal jam operasional layanan di kantor RTMC. Pada hari apa saja layanan tersebut tersedia. Terima kasih 3. Baik, Terima kasih atas informasinya🙏🏻 | H7: 1. siang juga kak.bisa lsg dtg ke polda gedung rtmc,sie stnk bawa bpkb asli,stnk asli,ktp asli di fto copy 2rangkap 2. senin - kamis 08.00 - 12.00 jumat - sabtu 08.00 - 11.00 3. sma2 kak
A8: 2 | B8: 46026 | C8: WHATSAPP | D8: +62 857-2118-9991 | E8: SAMSAT | F8: REGIDENT | G8: 1. Maaf mau bertanya, untuk pengurusan mutasi masuk kendaraan R2. Apakah hari Sabtu besok membuka layanan ? Serta persyaratan yg d bawa apa saja ya? Karena sebelumnya saya dari samsat tujuan d minta ke Polda Jatim. Apakah perlu membawakan kendraaan R2 nya ke Polda / cukup berkasnya saja ? 2. Ini saya perlu bawa kendaraan R2 nya atau cukup berkasnya saja ya ? Karena kemarin dari Samsat Talangagung, di minta ke polda setelah cek fisik 3. Baik, setelah verifikasi online nanti saya masukan kembali berkasnya ke Samsat Talangagung atau pencetakan STNK dn TNKB di Rtmc ? 4. Kak maaf satu lagi, Kendaraannya ga perlu di bawa ya? | H8: 1. buka kak untuk sabtu bsk jm8.00 - 11.00 wib 2. betul kak bawa berkas ke polda gedung rtmc sie stnk dan sie bpkb untuk proses kroscek dan verifikasi online 3. setelah proses di polda selesai baru di bawa ke samsat tujuan 4. sama2 kak 5. klau di polda tidak perlu kak 6. sma2 kak
A9: 3 | B9: 46026 | C9: WHATSAPP | D9: +62 895-3649-35567 | E9: SIM | F9: REGIDENT | G9: 1. Saya mau buat laporan atas pelaku penipuan di daerah gubeng sini musti ke polsek gubeng atau polres ya? 2. Baik, pengaduan atau lapor gitu sore masih bisa ya? | H9: 1. bisa di polres kak 2. bisa kak
A10: 1 | B10: 46027 | C10: WHATSAPP | D10: +62 856-5582-9982 | E10: SIM | F10: REGIDENT | G10: 1. Pagi kak 2. Persyaratan perpanjang sim apa aja 3. kalo di sim keliling area sidoarjo ada dimana kak 4. Untuk yg di lippo itu tutupnya jam brapa kak untuk sim cornernya 5. Pakai no antrian kah kak 6. Kalo yg di pondok candra itu di sebelah mananya pak | H10: 1. selamat pagi juga 2. foto copy ktp 3 lembar (ktp asli di bawa), foto copy sim 3 lembar (sim asli di bawa), untuk area sidoarjo ada di ramayana ciplas, 3. sampai jam 12.00 4. BETULA PAKAI ANTRIAN BAPAK 5. DI RUKO PALM BAPAK, ATAU SEBELAH TIMURNYA GIANT YANG SUDAH TUTUP
A11: 2 | B11: 46027 | C11: WHATSAPP | D11: +62 877-0288-1300 | E11: TILANG | F11: GAKKUM | G11: 1. Selamat pagi, RTMC Polda Jatim. Saya ingin bertanya mengenai pengurusan ganti stnk 5 tahunan di samsat sidoarjo, tapi kata pihak samsat bahwa kendaraan saya blokir etle polda , dan harus buka blokir di polda jatim, sedangkan saya tidak menerima sama sekali surat tilang untuk kendaaraan saya dan saya cek online data kendaraan saya memang tidak diketemukan pelanggaran. Mohon bantuan informasi nya terimakasih.🙏🏾 | H11: 1. bisa langsung konfirmasi di gedung pw polda jatim kak
A12: 3 | B12: 46027 | C12: WHATSAPP | D12: +62 852-3626-6344 | E12: TILANG | F12: GAKKUM | G12: 1. Saya ingin bertanya tentang cek etle untuk wilayah jawa timur | H12: 1. silakan datang ke polres / samsat terdekat
A13: 4 | B13: 46027 | C13: WHATSAPP | D13: +62 838-3068-2807 | E13: SAMSAT | F13: REGIDENT | G13: 1. Assalamu'alaikum pagi... Maaf, Samsat hari ini buka sampai jam brp?? 2. Klo kecamatan Sukodono mau ganti plat harus ke Samsat Krian kah??? Ap bisa klo di Samsat Sidoarjo Cemeng 3. Oh iya,,, ini berarti sy bayar pajak dan ganti plat 5 tahunan bisa di Samsat Sidoarjo Cemeng nggih🙏 4. Ini sy ke Samsat krian katanya ganti plat pindah ke trosobo 5. Bisa share alamat yg di trosobo | H13: 1. waalikumksalam, yan sampai jam 13.00 2. tidak bisa harus ke samsat asaL 3. jembatan timbang milik dishub /citra harmoni trosobo
... A175: 2 | B175: 46126 | C175: WHATSAPP | D175: 089677987686 | E175: TILANG | F175: GAKKUM | G175: 1. sudah mengisi data di web tapi belum dapat blangko via sms 2. baik pak | H175: 1. Ditunggu konfirmasi selanjut nya pak, kami sarankan untuk konfirmasi langsung ke Unit gakkum Polres
B176: 46128 | C176: WHATSAPP | D176: +62 811-3070-2826 | E176: TILANG | F176: GAKKUM | G176: 1. Nama: Rizki wahyu. Alamat: Wonorejo 4/31 surabaya. Informasi: Pengecekan apakah kena tilang etle. Saya cek di web error. | H176: 1. Untuk surat tilangnya dari mana bu? Mohon maaf untuk konfirmasi Etle masih ada perbaikan jaringan. 2. mohon waktu. silakan di byr untuk no briva nya sdh terlampir kak. 3. m banking bri. bisa lsg ke kcp bri kak. m bangking bri virtual accaount atau datang ke kcp bri terdekat.
A177: 1 | B177: 46128 | C177: WHATSAPP | D177: +62 822-6558-9819 | E177: SAMSAT | F177: REGIDENT | G177: 1. Nama: Luki Wahyuning T. Alamat: Tulungagung. Informasi: Izin tanya, jika pengambilan surat keterangan NRKB pilihan melewati/setelah tanggal yg tertera pada resi apakah diperbolehkan ya ? 2. Untuk pengambilan jika dikuasakan, apa saja persyaratan yg dibawa kak ? tidak perlu membawa bpkb dan stnk asli ya 3. Mohon info jam operasional kak | H177: 1. bisa diambil dan tidak apa apa kakak. 2. bisa melampirkan surat kuasa bertanda tangan diatas materai 10.000 dengan membawa ktp asli pemberi dan penerima kuasa. stnk asli di sertakan kakak. 3. Senin sd Sabtu Pukul 08.00 sd 13.00 Wib
A178: 2 | B178: 46128 | C178: WHATSAPP | D178: +62 822-5765-2986 | E178: TILANG | F178: GAKKUM | G178: 1. Nama: Eko Hidayat. Alamat: Benowo pasar rt re 01/01. Informasi: Mau buka blokir ETLE tidak bisa. Di suruh kembali lagi besok. Apakah aplikasi ETLE nya sudah bisa di gunakan? 2. Gak ada solusi kah kak? Kembali lagi seperti kemarin. 2 hari absen kerja. | H178: 1. halo kk terima kasih sdh menunggu untuk jaringan masih trobel besok bisa d proses seperti semula. 2. siap kk minta maaf ia kk insya ALLAH besok sdh bisa. 3. Mohon maaf atas ketidaknyamanannya.
A179: 1 | B179: 46128 | C179: WHATSAPP | D179: +62 878-5808-6000 | E179: TILANG | F179: GAKKUM | G179: 1. Nama: michael. Alamat: Jl. Pandean II/52. Informasi: tidak bisa bayar pajak mobil karena infonya ada tilang. 2. Hari ini sudah bisa ? Kemarin saya dari sana tapi infonya sistem masih error. Lokasi: Polda Jatim, jalan ahmad yani. | H179: 1. Silahkan di konfirmasi ke pusat pelayanan Etle terdekat, Polres atau Polda. 2. lokasi dimana kakak.
A180: 2 | B180: 46128 | C180: WHATSAPP | D180: +62 895-1590-0725 | E180: SIM | F180: REGIDENT | G180: 1. Mohon maaf mau tanya 剌 Untuk waktu SIM diterbitkan & masa berlaku SIM itu diisi sesuai yg tertera di SIM lama kah? | H180: 1. sesuai tanggal cetak terakhir yang ada di sim kakak
A181: 3 | B181: 46128 | C181: WHATSAPP | D181: +62 822-3421-0313 | E181: SIM | F181: REGIDENT | G181: 1. Nama: Gamma. Alamat: Bluru Kidul. Informasi/pengaduan: Untuk perpanjangan sim orang tua kandung | H181: apakah boleh dilakukan sang anak dengan surat kuasa dari orang tua nya ?
A182: 1 | B182: 46129 | C182: WHATSAPP | D182: +62 897-9799-904 | E182: TILANG | F182: GAKKUM | G182: 1. Nama : david. Alamat : pogot 10/19. Informasi/pengaduan : ETLE. Saya mau tnya kan kode referensi etle ,saya mau bayar lewat online pak 2. L4196CBC 3. Blum saya perbaiki simnya (masa berlaku mati) | H182: 1. bisa di fto stnk nya. bisa di ketik ulang nopol nya 2. Ijin pak pelanggarnya belum konfirmasi mgkn bisa dikirimkan simnya pak kami bantu konfirmasi dari sini. bisa di fto sim 3. masa berlaku sim sdh mati. bisa di fto sim terbaru. silakan di perbarui sim nya kak 4. saya confirm dlu ke operator nya. Ijin pak no briva dan no tilangnya Nopol L4196CBC
A183: 2 | B183: 46129 | C183: WHATSAPP | D183: +62 878-5392-1505 | E183: SIM | F183: REGIDENT | G183: 1. Nama : Andy. Alamat: jalan rambutan 7 He 06, pondok candra, Sidoarjo. Informasi: menanyakan layanan SIM keliling terdekat dari Pondok Candra Indah Sidoarjo, dan persyaratan dokumennya. 2. Mau tanya hari Sabtu apakah ada perpanjangan SIM keliling di pondok candra Sidoarjo? Kalau iya dari jam berapa-berapa ya? | H183: 1. ktp,sim asli di fto copy 3rangkap,tes sehat dan psikotes di sediakan di tkp
A184: 3 | B184: 46129 | C184: WHATSAPP | D184: +62 822-3481-9676 | E184: TILANG | F184: GAKKUM | G184: 1. Nama : marpuah. Alamat : dan. Buntut rt 04 rw08 tirtobinangun kab nganjuk. Informasi/pengaduan : cek data etle. Selamat siang saya mau cek data etle, karena STNK terblokir. 2. Tidak ada surat, hnya di beritahu samsat kalau ada etle, dan STNK diblokir. 3. Apakah setelah bayar denda STNK tidak lagi diblokir? Karena butuh untuk pengurusan pajak 5 tahunan. Cara bayarnya gimana ya. 4. Data tidak ditemukan (pada web kejaksaan). | H184: 1. bisa di fto surat etle nya. 2. setelah di byr lsg ke samsat menunjukan bukti byr nya. nanti untuk blokir terbuka. 3. https://tilang.kejaksaan.go.id masukan no reg tilang. 4. bisa di kirim fto sim.
A185: 1 | B185: 46129 | C185: WHATSAPP | D185: +62 823-3554-1927 | E185: SIM | F185: REGIDENT | G185: 1. Nama : Dani. Alamat : Jl. Medayu Utara XXXI no. 4 Rungkut - Surabaya. Informasi/pengaduan : Info Perpanjang SIM / SIM KELILING. 2. Sabtu buka kah kak? | H185: 1. bisa di yakaya kak. 2. betul kak. 3. buka kak jm08.00 - 12.00 wib
A186: 2 | B186: 46129 | C186: WHATSAPP | D186: +62 813-3612-5956 | E186: TILANG | F186: GAKKUM | G186: 1. Nama : Rudi s. Alamat : Pandegiling tengah 62. Informasi : etle surabaya. 2. L 1276 VG. 3. May minta info etle pak. Minta nomor tilang nya pak. Soal nya Surat nya hilang pak. 4. Stnk nya di rumah saya posisi di kejaksaan pak. | H186: 1. ada yang bisa dibantu kak. 2. siap kk ada yg bisa kami bantu kk. 3. stnk jenengan foto kk. 4. mohon waktu.
A187: 3 | B187: 46129 | C187: WHATSAPP | D187: +62 881-6264-375 | E187: SAMSAT | F187: REGIDENT | G187: 1. Nama: cholis yudianto. Alamat: bukit lawang indah blok u 2 lawang malang. Informasi: tidak bisa bayar stnk tahunan online karena ada blokir etle tapi cek tidak ada pelanggaran. 2. kalau ada etilang saya tidak ada surat nya tidak ada email nya saya juga tidak bisa cek online juga , bayar tilang pun tidak bisa secara online karena tidak ada data nya main blokir saja jadinya. 3. No berkas tilang saya berapa ? bisa dikasih tau. 4. Salah mobil saya warna merah. Bukan truk. 5. Tolong dibantu biar saya bisa perpanjang stnk saya secara online. | H187: 1. bisa di fto stnk nya. kami cek ke operator etle. 2. kami cek dlu untuk blokir nya. 3. Cek pak apa benar. apa benar untuk kendaraan nya. 4. bisa di fto kendaraan tampak depan dan belakang. 5. mohon waktu kami koordinasikan dlu untuk blokir nya. 6. silakan sdh terbuka untuk blokirnya. bisa di byr pjk nya.
A188: 1 | B188: 46129 | C188: WHATSAPP | D188: +62 823-3740-5543 | E188: TILANG | F188: GAKKUM | G188: 1. Nama: Octavan A. Alamat: kmp jagalan timur, kwanyar, bangkalan. Informasi: mau tanya, ini kendaraan mobil atas nama ibu saya mau perpanjang 5 tahunan, namun status kendaraan diblokir akibat etle surabaya, nah lantas apa yang harus dilakukan untuk membuka blokirna tersebut.. 2. Mau tanya apbila terkena tileng elektronik, namun tidak ddapat surat etle nya itu, ngeceknya dmn ? 3. Misalnya, terkena etle di sby, namun motornya itu domisili bangkalan, apa bisa cek di samsat bangkalan? | H188: 1. Bisa di fto surat etle nya kak. 2. di samsat terdekat loket blokir kak. 3. bisa kak. ke polres bagian gakkum lantas loket etle juga bisa kak.
... A300: 9 | B300: 46153 | C300: WHATSAPP | D300: +62 857-9134-7005 | E300: TILANG | F300: GAKKUM | G300: 1. Nama: Ishaq Yusron Akhsani. Alamat: Meri, Kranggan, Kota Mojokerto. 2. Permasalahan: Kendala teknis konfirmasi ETLE (No. Ref: 695-1F0C8-S1403SM) melalui web yang sempat error. Pelapor mempertanyakan status konfirmasi karena memegang surat fisik namun sempat diinformasikan data tidak ada oleh petugas. | H300: 1. Melakukan verifikasi ulang menggunakan foto STNK, SIM, dan surat fisik ETLE. 2. Menjelaskan bahwa nomor BRIVA berlaku 3 hari dan dapat dibayar via VA atau KCP BRI. 3. Mengarahkan pelapor untuk mengecek status konfirmasi dan blanko tilang secara mandiri melalui portal https://etilang.polri.go.id/.
A301: / | B301: 46154 | C301: WHATSAPP | D301: +62 812-1719-6308 | E301: SIM | F301: REGIDENT | G301: 1. Nama: Anggi Putra. Alamat: Anggaswangi, Sukodono. Informasi: Menanyakan kembali kepastian lokasi pelayanan SIM Keliling yang beroperasi pada hari ini (12 Mei 2026). | H301: 1. Menginformasikan lokasi SIM Keliling yang aktif hari ini berada di Pondok Tjandra, Kecamatan Sukodono, dan Ramayana Krian.
A302: 2 | B302: 46154 | C302: WHATSAPP | D302: +62 895-2316-9044 | E302: SIM | F302: REGIDENT | G302: 1. Menanyakan ketersediaan dan jadwal operasional SIM Keliling di Ciplaz Ramayana Sidoarjo. | H302: 1. Mengonfirmasi ketersediaan layanan di Ramayana Krian dan Ciplaz. 2. Menjelaskan jadwal operasional Senin s.d. Sabtu (kecuali hari Minggu dan tanggal merah) pukul 08.00 s.d. 12.00 WIB.
A303: 3 | B303: 46154 | C303: WHATSAPP | D303: +62 877-0276-6747 | E303: SIM | F303: REGIDENT | G303: 1. Nama: Angga Pahlevi. Alamat: Tanggulangin, Sidoarjo. 2. Informasi: Menanyakan lokasi SIM Keliling Sidoarjo, ketersediaan jadwal hari Sabtu/Minggu (karena kerja di hari kerja), serta status layanan di Lippo Mall/MPP Sidoarjo. | H303: 1. Menginformasikan lokasi aktif di Pondok Tjandra, Kec. Sukodono, dan Ramayana Krian. 2. Menjelaskan hari Minggu libur, namun hari Sabtu tetap buka pukul 08.00 s.d. 13.00 WIB. 3. Mengklarifikasi bahwa layanan di Lippo Mall sudah tidak ada.
A304: 4 | B304: 46154 | C304: TIKTOK | D304: Eci Naura | E304: SIM | F304: REGIDENT | G304: 1. Pelayanan SIM di Kecamatan Sukodono masih ada? 2. Kalau SIM mati sudah 2 tahun perpanjangannya berapa ongkosnya? | H304: 1. Masih 2. SIM yang telah habis masa berlakunya tidak dapat diperpanjang dan wajib membuat SIM baru
A305: 5 | B305: 46154 | C305: TIKTOK | D305: Keiko Traveling | E305: LAIN-LAIN | F305: GAKKUM | G305: 1. Pak tolong ditindak konten akun Tiktok Blackout dijalan tol. terimakasihj | H305: 1. Terimakasih atas informasinya, akan kami tindak lanjuti
A306: 6 | B306: 46154 | C306: TIKTOK | D306: AllisaS | E306: SIM | F306: REGIDENT | G306: 1. Perpanjang SIM di Kecamatan Sukodono apa masih ada? 2. Apa saja persyaratannya? | H306: 1. Masih ada dari senin - Sabtu 2. Membawa KTP dan SIM yang akan diperpanjang
A307: 7 | B307: 46154 | C307: TIKTOK | D307: ekoprasetya.id | E307: LAIN-LAIN | F307: LAIN-LAIN | G307: 1. Tolong pak ada pelanggar pengendara sepeda motor masuk ke jalur jembtan Suramadu malam malam kejadiannya | H307: 1. Terimakasih atas informasinya, akan kami tindak lanjuti
A308: 8 | B308: 46154 | C308: INSTAGRAM | D308: Murni Indriani | E308: SIM | F308: REGIDENT | G308: 1. Aplikasi untuk perpanjang SIM online apa? | H308: 1. Digital Korlantas Polri
A309: 9 | B309: 46154 | C309: WHATSAPP | D309: +62 822-3405-0917 | E309: SAMSAT | F309: REGIDENT | G309: 1. Nama: Adri Kurniawan. Alamat: Rungkut, Surabaya. 2. Informasi: Menanyakan status progres penerbitan BPKB pengganti (duplikat) dikarenakan dokumen asli hilang dan estimasi waktu penyelesaiannya. | H309: 1. Mengonfirmasi bahwa petugas akan menghubungi via WhatsApp jika BPKB sudah selesai. 2. Memberikan edukasi terkait estimasi waktu penerbitan BPKB duplikat yang membutuhkan waktu sekitar 6 bulan hingga 1 tahun.
A310: 1 | B310: 46155 | C310: WHATSAPP | D310: +62 812-3384-3287 | E310: SIM | F310: REGIDENT | G310: 1. Menanyakan ketersediaan layanan dan jadwal operasional SIM Keliling di wilayah Pondok Tjandra, Sidoarjo. | H310: 1. Mengonfirmasi ketersediaan layanan di Ruko Palm Pondok Tjandra. 2. Menginformasikan lokasi SIM Keliling Sidoarjo lainnya (Kec. Sukodono, Ramayana Krian, dan Ramayana Ciplaz) dengan jam operasional Senin-Sabtu pukul 08.00 s.d. 12.00 WIB.
A311: 2 | B311: 46155 | C311: WHATSAPP | D311: +62 813-3390-7553 | E311: TILANG | F311: GAKKUM | G311: 1. Nama: Agung. Alamat: Ngasem, Kediri. 2. Informasi: Kehilangan berkas surat ETLE dan ingin mengetahui nomor referensi untuk kendaraan AG 1127 GM (pelanggaran di Surabaya). | H311: 1. Meminta data identitas kendaraan (No. Rangka & No. Mesin) untuk pengecekan. 2. Menginformasikan terdapat 3 pelanggaran pada nopol tersebut. 3. Mengarahkan pelapor untuk mengecek detail data secara mandiri melalui portal resmi https://konfirmasi-etle.polri.go.id/cek-data.
A312: 3 | B312: 46155 | C312: WHATSAPP | D312: +62 822-3405-0917 | E312: SAMSAT | F312: REGIDENT | G312: 1. Nama: Adri Kurniawan. Alamat: Rungkut, Surabaya. 2. Informasi: Menanyakan status progres penerbitan BPKB pengganti (duplikat) dikarenakan dokumen asli hilang dan estimasi waktu penyelesaiannya. | H312: 1. Mengonfirmasi bahwa petugas akan menghubungi via WhatsApp jika BPKB sudah selesai. 2. Memberikan edukasi terkait estimasi waktu penerbitan BPKB duplikat yang membutuhkan waktu sekitar 6 bulan hingga 1 tahun.
...
